I'm sorry, but an uncaught exception occurred.

While running game code:
  File "game/script.rpy", line 63, in script call
    call scene16
  File "game/chapter2/scene16.rpy", line 4, in script
    if result == "success":
  File "game/chapter2/scene16.rpy", line 4, in <module>
    if result == "success":
NameError: name 'result' is not defined

-- Full Traceback ------------------------------------------------------------

Full traceback:
  File "game/script.rpy", line 63, in script call
    call scene16
  File "game/chapter2/scene16.rpy", line 4, in script
    if result == "success":
  File "/mnt/windows/renpy-8.3.4-sdk/renpy/ast.py", line 1849, in execute
    if renpy.python.py_eval(condition):
  File "/mnt/windows/renpy-8.3.4-sdk/renpy/python.py", line 1209, in py_eval
    return py_eval_bytecode(code, globals, locals)
  File "/mnt/windows/renpy-8.3.4-sdk/renpy/python.py", line 1202, in py_eval_bytecode
    return eval(bytecode, globals, locals)
  File "game/chapter2/scene16.rpy", line 4, in <module>
    if result == "success":
NameError: name 'result' is not defined

Linux-6.12.7-zen1-1-zen-x86_64-with-glibc2.40 x86_64
Ren'Py 8.3.4.24120703
DreamEngine 1.0
Mon Dec 30 20:37:06 2024
